<?xml version="1.0" ?>
<!-- =================================================================================== -->
<!-- |    This document was autogenerated by xacro from workspace/ros_dumpster/src/universal_robot/ur_e_description/urdf/ur10e_joint_limited_robot.urdf.xacro | -->
<!-- |    EDITING THIS FILE BY HAND IS NOT RECOMMENDED                                 | -->
<!-- =================================================================================== -->
<robot name="ur10e">
 <!--
  Author: Kelsey Hawkins
  Contributers: Jimmy Da Silva, Ajit Krisshna N L, Muhammad Asif Rana
-->

  <material name="LightGrey">
    <color rgba="0.7 0.7 0.7 1.0"/>
  </material>

  <material name="LightBlue">
    <color rgba="0.1 0.7 1 1.0"/>
  </material>

  <material name="DarkGrey">
    <color rgba="0.2 0.2 0.2 1.0"/>
  </material>

  <material name="panda_white">
    <color rgba="0.05 0.05 0.05 1."/>
  </material>

  <link name="base_link">
    <visual>
      <geometry>
        <mesh filename="package://UR10e_description/robot/meshs/visual/base.dae"/>
      </geometry>
      <material name="LightGrey"/>
    </visual>
    <collision>
      <geometry>
        <mesh filename="package://UR10e_description/robot/meshs/collision/base.obj"/>
      </geometry>
    </collision>
    <inertial>
      <!-- alper: originally, mass was 4.0 -->
      <mass value="0.0"/> 
      <origin rpy="0 0 0" xyz="0.0 0.0 0.0"/>
      <inertia ixx="0.0061063308908" ixy="0.0" ixz="0.0" iyy="0.0061063308908" iyz="0.0" izz="0.01125"/>
    </inertial>
  </link>

  <joint name="shoulder_pan_joint" type="revolute">
    <parent link="base_link"/>
    <child link="shoulder_link"/>
    <origin rpy="0.0 0.0 0.0" xyz="0.0 0.0 0.181"/>
    <axis xyz="0 0 1"/>
    <limit effort="330.0" lower="-3.141592653589793" upper="3.141592653589793" velocity="3.14"/>
    <dynamics damping="0.0" friction="0.0"/>
  </joint>

  <link name="shoulder_link">
    <visual>
      <geometry>
        <mesh filename="package://UR10e_description/robot/meshs/visual/shoulder.dae"/>
      </geometry>
      <material name="DarkGrey"/>
    </visual>
    <collision>
      <geometry>
        <mesh filename="package://UR10e_description/robot/meshs/collision/shoulder.obj"/>
      </geometry>
    </collision>
    <inertial>
      <mass value="7.778"/>
      <origin rpy="0 0 0" xyz="0.0 0.0 0.0"/>
      <inertia ixx="0.03147431257693659" ixy="0.0" ixz="0.0" iyy="0.03147431257693659" iyz="0.0" izz="0.021875624999999996"/>
    </inertial>
  </link>

  <joint name="shoulder_lift_joint" type="revolute">
    <parent link="shoulder_link"/>
    <child link="upper_arm_link"/>
    <origin rpy="0.0 1.5707963267948966 0.0" xyz="0.0 0.176 0.0"/>
    <axis xyz="0 1 0"/>
    <limit effort="330.0" lower="-3.141592653589793" upper="3.141592653589793" velocity="3.14"/>
    <dynamics damping="0.0" friction="0.0"/>
  </joint>

  <link name="upper_arm_link">
    <visual>
      <geometry>
        <mesh filename="package://UR10e_description/robot/meshs/visual/upperarm.dae"/>
      </geometry>
      <material name="LightGrey"/>
    </visual>
    <collision>
      <geometry>
        <mesh filename="package://UR10e_description/robot/meshs/collision/upperarm.obj"/>
      </geometry>
    </collision>
    <inertial>
      <mass value="12.93"/>
      <origin rpy="0 0 0" xyz="0.0 0.0 0.3065"/>
      <inertia ixx="0.4230737407704359" ixy="0.0" ixz="0.0" iyy="0.4230737407704359" iyz="0.0" izz="0.03636562499999999"/>
    </inertial>
  </link>

  <joint name="elbow_joint" type="revolute">
    <parent link="upper_arm_link"/>
    <child link="forearm_link"/>
    <origin rpy="0.0 0.0 0.0" xyz="0.0 -0.137 0.613"/>
    <axis xyz="0 1 0"/>
    <limit effort="150.0" lower="-3.141592653589793" upper="3.141592653589793" velocity="3.14"/>
    <dynamics damping="0.0" friction="0.0"/>
  </joint>

  <link name="forearm_link">
    <visual>
      <geometry>
        <mesh filename="package://UR10e_description/robot/meshs/visual/forearm.dae"/>
      </geometry>
      <material name="DarkGrey"/>
    </visual>
    <collision>
      <geometry>
        <mesh filename="package://UR10e_description/robot/meshs/collision/forearm.obj"/>
      </geometry>
    </collision>
    <inertial>
      <mass value="3.87"/>
      <origin rpy="0 0 0" xyz="0.0 0.0 0.2855"/>
      <inertia ixx="0.11059036576383598" ixy="0.0" ixz="0.0" iyy="0.11059036576383598" iyz="0.0" izz="0.010884375"/>
    </inertial>
  </link>

  <joint name="wrist_1_joint" type="revolute">
    <parent link="forearm_link"/>
    <child link="wrist_1_link"/>
    <origin rpy="0.0 1.5707963267948966 0.0" xyz="0.0 0.0 0.571"/>
    <axis xyz="0 1 0"/>
    <limit effort="54.0" lower="-3.141592653589793" upper="3.141592653589793" velocity="6.28"/>
    <dynamics damping="0.0" friction="0.0"/>
  </joint>

  <link name="wrist_1_link">
    <visual>
      <geometry>
        <mesh filename="package://UR10e_description/robot/meshs/visual/wrist1.dae"/>
      </geometry>
      <material name="LightGrey"/>
    </visual>
    <collision>
      <geometry>
        <mesh filename="package://UR10e_description/robot/meshs/collision/wrist1.obj"/>
      </geometry>
    </collision>
    <inertial>
      <mass value="1.96"/>
      <origin rpy="0 0 0" xyz="0.0 0.135 0.0"/>
      <inertia ixx="0.005108247956699999" ixy="0.0" ixz="0.0" iyy="0.005108247956699999" iyz="0.0" izz="0.005512499999999999"/>
    </inertial>
  </link>

  <joint name="wrist_2_joint" type="revolute">
    <parent link="wrist_1_link"/>
    <child link="wrist_2_link"/>
    <origin rpy="0.0 0.0 0.0" xyz="0.0 0.135 0.0"/>
    <axis xyz="0 0 1"/>
    <limit effort="54.0" lower="-3.141592653589793" upper="3.141592653589793" velocity="6.28"/>
    <dynamics damping="0.0" friction="0.0"/>
  </joint>

  <link name="wrist_2_link">
    <visual>
      <geometry>
        <mesh filename="package://UR10e_description/robot/meshs/visual/wrist2.dae"/>
      </geometry>
      <material name="DarkGrey"/>
    </visual>
    <collision>
      <geometry>
        <mesh filename="package://UR10e_description/robot/meshs/collision/wrist2.obj"/>
      </geometry>
    </collision>
    <inertial>
      <mass value="1.96"/>
      <origin rpy="0 0 0" xyz="0.0 0.0 0.12"/>
      <inertia ixx="0.005108247956699999" ixy="0.0" ixz="0.0" iyy="0.005108247956699999" iyz="0.0" izz="0.005512499999999999"/>
    </inertial>
  </link>

  <joint name="wrist_3_joint" type="revolute">
    <parent link="wrist_2_link"/>
    <child link="wrist_3_link"/>
    <origin rpy="0.0 0.0 0.0" xyz="0.0 0.0 0.12"/>
    <axis xyz="0 1 0"/>
    <limit effort="54.0" lower="-3.141592653589793" upper="3.141592653589793" velocity="6.28"/>
    <dynamics damping="0.0" friction="0.0"/>
  </joint>

  <link name="wrist_3_link">
    <visual>
      <geometry>
        <mesh filename="package://UR10e_description/robot/meshs/visual/wrist3.dae"/>
      </geometry>
      <material name="LightGrey"/>
    </visual>
    <collision>
      <geometry>
        <mesh filename="package://UR10e_description/robot/meshs/collision/wrist3.obj"/>
      </geometry>
    </collision>
    <inertial>
      <mass value="0.202"/>
      <origin rpy="1.5707963267948966 0 0" xyz="0.0 0.092 0.0"/>
      <inertia ixx="0.00014434577559500002" ixy="0.0" ixz="0.0" iyy="0.00014434577559500002" iyz="0.0" izz="0.00020452500000000002"/>
    </inertial>
  </link>

  <joint name="tool0_fixed_joint" type="fixed">
    <origin rpy="0 3.141592653589793 0" xyz="0 0.137 0"/> # 0.117
    <parent link="wrist_3_link"/>
    <child link="ma"/>
  </joint>

  <link name="ma">
    <inertial>
      <origin xyz="0 0 0" rpy="0 1.5707963267949 0" /> 
      <mass value="5E-05" />
      <inertia
        ixx="2.0754E-07"
        ixy="0"
        ixz="0"
        iyy="4.1508E-07"
        iyz="-1.27077401336148E-23"
        izz="2.0754E-07" />
    </inertial>
    <visual>
      <origin xyz="0 0 0" rpy="0 1.5707963267949 0" />
      <geometry>
        <mesh filename="package://UR10e_description/ma/meshes/ma.dae" />
      </geometry>
      <material
        name="">
        <color
          rgba="0.5 0 0.5 1" />
      </material>
    </visual>
    <collision>
      <origin xyz="0 0 0" rpy="0 1.5707963267949 0" />
      <geometry>
        <mesh filename="package://UR10e_description/ma/meshes/ma.obj" />
      </geometry>
    </collision>
  </link>

</robot>
